<?xml version="1.0" encoding="UTF-8"?>
<!-- Generated by org.testng.reporters.JUnitXMLReporter -->
<testsuite ignored="0" hostname="DESKTOP-1FKFP5A" failures="2" tests="6" name="testing listener" time="0.869" errors="0" timestamp="26 Apr 2020 15:22:34 GMT">
  <testcase classname="Testlistener" name="tc_01" time="0.013"/>
  <testcase classname="Testlistener" name="tc_02" time="0.009">
    <failure type="java.lang.AssertionError" message="expected [0] but found [1]">
      <![CDATA[java.lang.AssertionError: expected [0] but found [1]
at Testlistener.tc_02(Testlistener.java:14)
at java.base/java.util.concurrent.FutureTask.run(FutureTask.java:264)
at java.base/java.util.concurrent.ThreadPoolExecutor.runWorker(ThreadPoolExecutor.java:1167)
at java.base/java.util.concurrent.ThreadPoolExecutor$Worker.run(ThreadPoolExecutor.java:641)
at java.base/java.lang.Thread.run(Thread.java:844)
... Removed 22 stack frames]]>
    </failure>
  </testcase> <!-- tc_02 -->
  <testcase classname="Testlistener" name="tc_03" time="0.002"/>
  <testcase classname="Testlistener" name="tc_04" time="0.002"/>
  <testcase classname="testnddemo" name="m1" time="0.002">
    <failure type="java.lang.AssertionError" message="expected [1] but found [0]">
      <![CDATA[java.lang.AssertionError: expected [1] but found [0]
at testnddemo.m1(testnddemo.java:11)
at java.base/java.util.concurrent.FutureTask.run(FutureTask.java:264)
at java.base/java.util.concurrent.ThreadPoolExecutor.runWorker(ThreadPoolExecutor.java:1167)
at java.base/java.util.concurrent.ThreadPoolExecutor$Worker.run(ThreadPoolExecutor.java:641)
at java.base/java.lang.Thread.run(Thread.java:844)
... Removed 22 stack frames]]>
    </failure>
  </testcase> <!-- m1 -->
  <testcase classname="testnddemo" name="m2" time="0.002"/>
</testsuite> <!-- testing listener -->
